Workbook

Sheet Sheet1
A1: Month_End | B1: PnL_Distribution
A2: 45869 | B2: ='Sheet1 (2)'!Q2 -> -9.6515568 | D2: =500-90%*500 -> 50
A3: 45838 | B3: ='Sheet1 (2)'!Q3 -> 123.8389
A4: 45808 | B4: ='Sheet1 (2)'!Q4 -> 68.79205
A5: 45777 | B5: ='Sheet1 (2)'!Q5 -> 46.68104
A6: 45747 | B6: ='Sheet1 (2)'!Q6 -> 56.036506
A7: 45716 | B7: ='Sheet1 (2)'!Q7 -> 112.1704
A8: 45688 | B8: ='Sheet1 (2)'!Q8 -> 47.607323
A9: 45657 | B9: ='Sheet1 (2)'!Q9 -> -52.956991
A10: 45626 | B10: ='Sheet1 (2)'!Q10 -> 44.078777
A11: 45596 | B11: ='Sheet1 (2)'!Q11 -> -53.206124
A12: 45565 | B12: ='Sheet1 (2)'!Q12 -> -39.376147
A13: 45535 | B13: ='Sheet1 (2)'!Q13 -> 45.5126
A14: 45504 | B14: ='Sheet1 (2)'!Q14 -> 36.795242
... A15501: 44957 | B15501: ='Sheet1 (2)'!Q15501 -> -47.644812

Sheet Sheet1 (2)
A1: Month_End | B1: PnL_Distribution | G1: SELECT | N1: ITEM_NAME | O1: AS_OF_DATE | P1: TOTAL_ITEM_VALUE | Q1: SAME IN USDm | V1: Month_End | W1: PnL_Distribution
A2: 45869 | B2: -9651556.8 | G2: ITEM_NAME, | N2: PNL_500D_10D99_HVAR_SCENARIO_1 | O2: 45869 | P2: -9651556.8 | Q2: =P2/1000000 -> -9.6515568 | V2: 45869 | W2: -2.0857371e+08 | X2: =_xlfn.STDEV.P(W2:W501) -> 81327030 | AF2: =500-90%*500 -> 50
A3: 45838 | B3: 1.238389e+08 | G3: AS_OF_DATE, | N3: PNL_500D_10D99_HVAR_SCENARIO_1 | O3: 45838 | P3: 1.238389e+08 | Q3: =P3/1000000 -> 123.8389 | V3: 45869 | W3: -2.0690011e+08 | Z3: Row Labels | AA3: Sum of PnL_Distribution
A4: 45808 | B4: 68792050 | G4: SUM(ITEM_VALUE) AS TOTAL_ITEM_VALUE | N4: PNL_500D_10D99_HVAR_SCENARIO_1 | O4: 45808 | P4: 68792050 | Q4: =P4/1000000 -> 68.79205 | V4: 45869 | W4: -2.065054e+08 | Z4: 44957 | AA4: -5.7610439e+09 | AC4: =AA4/500 -> -11522088
A5: 45777 | B5: 46681040 | G5: FROM ( | N5: PNL_500D_10D99_HVAR_SCENARIO_1 | O5: 45777 | P5: 46681040 | Q5: =P5/1000000 -> 46.68104 | V5: 45869 | W5: -2.0110738e+08 | Z5: 44985 | AA5: -8.1162921e+09 | AC5: =AA5/500 -> -16232584
A6: 45747 | B6: 56036506 | G6: SELECT ITEM_NAME, AS_OF_DATE, ITEM_VALUE | N6: PNL_500D_10D99_HVAR_SCENARIO_1 | O6: 45747 | P6: 56036506 | Q6: =P6/1000000 -> 56.036506 | V6: 45869 | W6: -1.9278358e+08 | Z6: 45016 | AA6: -8.5243676e+09 | AC6: =AA6/500 -> -17048735
A7: 45716 | B7: 1.121704e+08 | G7: FROM DMS_OUT_MARS_MUTEDRISK_VARPNL | N7: PNL_500D_10D99_HVAR_SCENARIO_1 | O7: 45716 | P7: 1.121704e+08 | Q7: =P7/1000000 -> 112.1704 | V7: 45869 | W7: -1.8943678e+08 | Z7: 45044 | AA7: -8.2968274e+09 | AC7: =AA7/500 -> -16593655
A8: 45688 | B8: 47607323 | G8: WHERE AIIB_MUTED_CS_RISK_NODE_NAME = 'Firm' | N8: PNL_500D_10D99_HVAR_SCENARIO_1 | O8: 45688 | P8: 47607323 | Q8: =P8/1000000 -> 47.607323 | V8: 45869 | W8: -1.7148528e+08 | Z8: 45077 | AA8: -8.6742454e+09 | AC8: =AA8/500 -> -17348491
A9: 45657 | B9: -52956991 | G9: AND ITEM_NAME LIKE '%_99_HVAR_SCENARIO%' | N9: PNL_500D_10D99_HVAR_SCENARIO_1 | O9: 45657 | P9: -52956991 | Q9: =P9/1000000 -> -52.956991 | V9: 45869 | W9: -1.7074996e+08 | Z9: 45107 | AA9: -8.1016041e+09 | AC9: =AA9/500 -> -16203208
A10: 45626 | B10: 44078777 | G10: AND AS_OF_DATE >= '2023-01-31' | N10: PNL_500D_10D99_HVAR_SCENARIO_1 | O10: 45626 | P10: 44078777 | Q10: =P10/1000000 -> 44.078777 | V10: 45869 | W10: -1.6887365e+08 | Z10: 45138 | AA10: -8.6703051e+09 | AC10: =AA10/500 -> -17340610
A11: 45596 | B11: -53206124 | G11: AND AS_OF_DATE = EOMONTH(AS_OF_DATE) | N11: PNL_500D_10D99_HVAR_SCENARIO_1 | O11: 45596 | P11: -53206124 | Q11: =P11/1000000 -> -53.206124 | V11: 45869 | W11: -1.6637417e+08 | Z11: 45169 | AA11: -9.4644992e+09 | AC11: =AA11/500 -> -18928998
A12: 45565 | B12: -39376147 | N12: PNL_500D_10D99_HVAR_SCENARIO_1 | O12: 45565 | P12: -39376147 | Q12: =P12/1000000 -> -39.376147 | V12: 45869 | W12: -1.6544964e+08 | Z12: 45199 | AA12: -9.405957e+09 | AC12: =AA12/500 -> -18811914
A13: 45535 | B13: 45512600 | G13: UNION ALL | N13: PNL_500D_10D99_HVAR_SCENARIO_1 | O13: 45535 | P13: 45512600 | Q13: =P13/1000000 -> 45.5126 | V13: 45869 | W13: -1.5935553e+08 | Z13: 45230 | AA13: -8.1240121e+09 | AC13: =AA13/500 -> -16248024
A14: 45504 | B14: 36795242 | N14: PNL_500D_10D99_HVAR_SCENARIO_1 | O14: 45504 | P14: 36795242 | Q14: =P14/1000000 -> 36.795242 | V14: 45869 | W14: -1.5933142e+08 | Z14: 45260 | AA14: -7.2448821e+09 | AC14: =AA14/500 -> -14489764
A15: 45473 | B15: -28254491 | G15: SELECT ITEM_NAME, AS_OF_DATE, ITEM_VALUE | N15: PNL_500D_10D99_HVAR_SCENARIO_1 | O15: 45473 | P15: -28254491 | Q15: =P15/1000000 -> -28.254491 | V15: 45869 | W15: -1.5897521e+08 | Z15: 45291 | AA15: -5.6470088e+09 | AC15: =AA15/500 -> -11294018
A16: 45443 | B16: -15180150 | G16: FROM DMS_OUT_MARS_FULLRISK_VARPNL | N16: PNL_500D_10D99_HVAR_SCENARIO_1 | O16: 45443 | P16: -15180150 | Q16: =P16/1000000 -> -15.18015 | V16: 45869 | W16: -1.5198155e+08 | Z16: 45322 | AA16: -5.0816444e+09 | AC16: =AA16/500 -> -10163289
A17: 45412 | B17: -7312622.2 | G17: WHERE AIIB_FULL_RISK_FACTOR_NODE_NAME = 'Firm' | N17: PNL_500D_10D99_HVAR_SCENARIO_1 | O17: 45412 | P17: -7312622.2 | Q17: =P17/1000000 -> -7.3126222 | V17: 45869 | W17: -1.4675659e+08 | Z17: 45351 | AA17: -4.854997e+09 | AC17: =AA17/500 -> -9709994
A18: 45382 | B18: 1906556.3 | G18: AND ITEM_NAME LIKE '%_99_HVAR_SCENARIO%' | N18: PNL_500D_10D99_HVAR_SCENARIO_1 | O18: 45382 | P18: 1906556.3 | Q18: =P18/1000000 -> 1.9065563 | V18: 45869 | W18: -1.466272e+08 | Z18: 45382 | AA18: -3.6312255e+09 | AC18: =AA18/500 -> -7262450.9
A19: 45351 | B19: -14483410 | G19: AND AS_OF_DATE >= '2023-01-31' | N19: PNL_500D_10D99_HVAR_SCENARIO_1 | O19: 45351 | P19: -14483410 | Q19: =P19/1000000 -> -14.48341 | V19: 45869 | W19: -1.4575112e+08 | Z19: 45412 | AA19: -4.6515312e+09 | AC19: =AA19/500 -> -9303062.4
A20: 45322 | B20: 38603207 | G20: AND AS_OF_DATE = EOMONTH(AS_OF_DATE) | N20: PNL_500D_10D99_HVAR_SCENARIO_1 | O20: 45322 | P20: 38603207 | Q20: =P20/1000000 -> 38.603207 | V20: 45869 | W20: -1.4526246e+08 | Z20: 45443 | AA20: -3.1193465e+09 | AC20: =AA20/500 -> -6238693.1
A21: 45291 | B21: 41905309 | G21: ) AS combined | N21: PNL_500D_10D99_HVAR_SCENARIO_1 | O21: 45291 | P21: 41905309 | Q21: =P21/1000000 -> 41.905309 | V21: 45869 | W21: -1.4469099e+08 | Z21: 45473 | AA21: -2.6511138e+09 | AC21: =AA21/500 -> -5302227.6
A22: 45260 | B22: 54338075 | G22: GROUP BY ITEM_NAME, AS_OF_DATE | N22: PNL_500D_10D99_HVAR_SCENARIO_1 | O22: 45260 | P22: 54338075 | Q22: =P22/1000000 -> 54.338075 | V22: 45869 | W22: -1.4343843e+08 | Z22: 45504 | AA22: -5.4846243e+08 | AC22: =AA22/500 -> -1096924.9
A23: 45230 | B23: 51959795 | G23: ORDER BY ITEM_NAME, AS_OF_DATE DESC; | N23: PNL_500D_10D99_HVAR_SCENARIO_1 | O23: 45230 | P23: 51959795 | Q23: =P23/1000000 -> 51.959795 | V23: 45869 | W23: -1.4215034e+08 | Z23: 45535 | AA23: 3.9594347e+09 | AC23: =AA23/500 -> 7918869.5
A24: 45199 | B24: -20766701 | N24: PNL_500D_10D99_HVAR_SCENARIO_1 | O24: 45199 | P24: -20766701 | Q24: =P24/1000000 -> -20.766701 | V24: 45869 | W24: -1.3905063e+08 | Z24: 45565 | AA24: 6.1380306e+09 | AC24: =AA24/500 -> 12276061
A25: 45169 | B25: 36990445 | N25: PNL_500D_10D99_HVAR_SCENARIO_1 | O25: 45169 | P25: 36990445 | Q25: =P25/1000000 -> 36.990445 | V25: 45869 | W25: -1.3426964e+08 | Z25: 45596 | AA25: 2.1344035e+09 | AC25: =AA25/500 -> 4268806.9
A26: 45138 | B26: -8501024.9 | N26: PNL_500D_10D99_HVAR_SCENARIO_1 | O26: 45138 | P26: -8501024.9 | Q26: =P26/1000000 -> -8.5010249 | V26: 45869 | W26: -1.3372277e+08 | Z26: 45626 | AA26: 1.2310334e+09 | AC26: =AA26/500 -> 2462066.9
A27: 45107 | B27: -7344270.6 | N27: PNL_500D_10D99_HVAR_SCENARIO_1 | O27: 45107 | P27: -7344270.6 | Q27: =P27/1000000 -> -7.3442706 | V27: 45869 | W27: -1.333347e+08 | Z27: 45657 | AA27: -1.0496633e+09 | AC27: =AA27/500 -> -2099326.7
A28: 45077 | B28: -5172168.2 | N28: PNL_500D_10D99_HVAR_SCENARIO_1 | O28: 45077 | P28: -5172168.2 | Q28: =P28/1000000 -> -5.1721682 | V28: 45869 | W28: -1.2764683e+08 | Z28: 45688 | AA28: 2.2292262e+09 | AC28: =AA28/500 -> 4458452.3
A29: 45044 | B29: 6035454.9 | N29: PNL_500D_10D99_HVAR_SCENARIO_1 | O29: 45044 | P29: 6035454.9 | Q29: =P29/1000000 -> 6.0354549 | V29: 45869 | W29: -1.2727774e+08 | Z29: 45716 | AA29: 1.0457384e+09 | AC29: =AA29/500 -> 2091476.7
A30: 45016 | B30: -62319552 | N30: PNL_500D_10D99_HVAR_SCENARIO_1 | O30: 45016 | P30: -62319552 | Q30: =P30/1000000 -> -62.319552 | V30: 45869 | W30: -1.2623359e+08 | Z30: 45747 | AA30: 2.1807005e+09 | AC30: =AA30/500 -> 4361401.1
A31: 44985 | B31: -28492601 | N31: PNL_500D_10D99_HVAR_SCENARIO_1 | O31: 44985 | P31: -28492601 | Q31: =P31/1000000 -> -28.492601 | V31: 45869 | W31: -1.2405622e+08 | Z31: 45777 | AA31: 3.8391635e+09 | AC31: =AA31/500 -> 7678326.9
A32: 44957 | B32: -12228513 | N32: PNL_500D_10D99_HVAR_SCENARIO_1 | O32: 44957 | P32: -12228513 | Q32: =P32/1000000 -> -12.228513 | V32: 45869 | W32: -1.2239156e+08 | Z32: 45808 | AA32: 4.2418208e+09 | AC32: =AA32/500 -> 8483641.6
A33: 45869 | B33: -9928532.1 | N33: PNL_500D_10D99_HVAR_SCENARIO_10 | O33: 45869 | P33: -9928532.1 | Q33: =P33/1000000 -> -9.9285321 | V33: 45869 | W33: -1.1838357e+08 | Z33: 45838 | AA33: 5.484107e+09 | AC33: =AA33/500 -> 10968214
A34: 45838 | B34: 14507975 | N34: PNL_500D_10D99_HVAR_SCENARIO_10 | O34: 45838 | P34: 14507975 | Q34: =P34/1000000 -> 14.507975 | V34: 45869 | W34: -1.0890371e+08 | Z34: 45869 | AA34: 6.2396401e+09 | AC34: =AA34/500 -> 12479280
A35: 45808 | B35: -81151414 | N35: PNL_500D_10D99_HVAR_SCENARIO_10 | O35: 45808 | P35: -81151414 | Q35: =P35/1000000 -> -81.151414 | V35: 45869 | W35: -1.0823346e+08 | Z35: Grand Total | AA35: -8.289573e+10
A36: 45777 | B36: -30223952 | N36: PNL_500D_10D99_HVAR_SCENARIO_10 | O36: 45777 | P36: -30223952 | Q36: =P36/1000000 -> -30.223952 | V36: 45869 | W36: -1.0617841e+08
A37: 45747 | B37: 20918735 | N37: PNL_500D_10D99_HVAR_SCENARIO_10 | O37: 45747 | P37: 20918735 | Q37: =P37/1000000 -> 20.918735 | V37: 45869 | W37: -98523699
A38: 45716 | B38: 20049704 | N38: PNL_500D_10D99_HVAR_SCENARIO_10 | O38: 45716 | P38: 20049704 | Q38: =P38/1000000 -> 20.049704 | V38: 45869 | W38: -97064872
A39: 45688 | B39: -11833206 | N39: PNL_500D_10D99_HVAR_SCENARIO_10 | O39: 45688 | P39: -11833206 | Q39: =P39/1000000 -> -11.833206 | V39: 45869 | W39: -95785736
A40: 45657 | B40: -1.4161698e+08 | N40: PNL_500D_10D99_HVAR_SCENARIO_10 | O40: 45657 | P40: -1.4161698e+08 | Q40: =P40/1000000 -> -141.61698 | V40: 45869 | W40: -95073536
...
